<?xml version="1.0" encoding="utf-8"?>
<robot>
  <link
      name="head_yaw">
      <inertial>
        <origin
          xyz="0.0192090313803226 -0.000209732444885397 -0.00477606520095217"
          rpy="0 0 0" />
        <mass
          value="0.0573922743530686" />
        <inertia
          ixx="5.98272304285402E-07"
          ixy="-9.55132100709239E-09"
          ixz="2.00959509125472E-06"
          iyy="7.34863588332809E-06"
          iyz="2.84343934345717E-09"
          izz="6.7503906079721E-06" />
      </inertial>
      <visual>
        <origin
          xyz="0 0 0"
          rpy="0 0 0" />
        <geometry>
          <mesh
            filename="package://gummi_head_$(env ROS_GUMMI_HEAD)/meshes/head_yaw.stl" />
        </geometry>
        <material
          name="">
          <color
            rgba="0.792156862745098 0.819607843137255 0.933333333333333 1" />
        </material>
      </visual>
      <collision>
        <origin
          xyz="0 0 0"
          rpy="0 0 0" />
        <geometry>
          <mesh
            filename="package://gummi_head_$(env ROS_GUMMI_HEAD)/meshes/head_yaw_CH.stl" />
        </geometry>
      </collision>
    </link>
    <joint
      name="head_yaw"
      type="revolute">
      <origin
        xyz="0.005 0.1 0.188"
        rpy="3.14159265359 0 0" />
      <parent
        link="base_link" />
      <child
        link="head_yaw" />
      <axis
        xyz="0 0 -1" />
      <limit
        lower="-1.56"
        upper="1.56"
        effort="0"
        velocity="1" />
    </joint>
    <link
        name="head_pitch">
        <inertial>
          <origin
            xyz="0.0192090313803226 -0.000209732444885397 -0.00477606520095217"
            rpy="0 0 0" />
          <mass
            value="0.0573922743530686" />
          <inertia
            ixx="5.98272304285402E-07"
            ixy="-9.55132100709239E-09"
            ixz="2.00959509125472E-06"
            iyy="7.34863588332809E-06"
            iyz="2.84343934345717E-09"
            izz="6.7503906079721E-06" />
        </inertial>
        <visual>
          <origin
            xyz="0 0 0"
            rpy="0 0 0" />
          <geometry>
            <mesh
              filename="package://gummi_head_$(env ROS_GUMMI_HEAD)/meshes/head_pitch.stl" />
          </geometry>
          <material
            name="">
            <color
              rgba="0.792156862745098 0.819607843137255 0.933333333333333 1" />
          </material>
        </visual>
        <collision>
          <origin
            xyz="0 0 0"
            rpy="0 0 0" />
          <geometry>
            <mesh
              filename="package://gummi_head_$(env ROS_GUMMI_HEAD)/meshes/head_pitch_CH.stl" />
          </geometry>
        </collision>
      </link>
      <joint
        name="head_pitch"
        type="revolute">
        <origin
          xyz="0 0 -0.051202"
          rpy="-1.57079632679 0.0436332 -0.0349066" />
        <parent
          link="head_yaw" />
        <child
          link="head_pitch" />
        <axis
          xyz="0 0 1" />
        <limit
         lower="-0.7853"
          upper="0.7853"
          effort="0"
          velocity="1" />
      </joint>
      <link
        name="camera">
        <inertial>
          <origin
           xyz="0.0484512742480244 0.0139768664666073 0.000956995637939325"
           rpy="0 0 0" />
        <mass
           value="0.0644774651698934" />
        <inertia
        ixx="8.67406414845019E-06"
        ixy="-1.3193756197629E-05"
        ixz="-3.41916035169704E-06"
        iyy="4.217442276821E-05"
        iyz="-4.04257224014858E-07"
        izz="4.91399139463636E-05" />
        </inertial>
        <visual>
          <origin
          xyz="0 0 0"
          rpy="0 0 0" />
        <geometry>
          <mesh
           filename="package://gummi_head_$(env ROS_GUMMI_HEAD)/meshes/realsense_CH.stl" />
        </geometry>
        <material
          name="">
          <color
            rgba="0.792156862745098 0.819607843137255 0.933333333333333 1" />
        </material>
        </visual>
        <collision>
          <origin
            xyz="0 0 0"
            rpy="0 0 0" />
        <geometry>
         <mesh
            filename="package://gummi_head_$(env ROS_GUMMI_HEAD)/meshes/realsense_CH.stl" />
        </geometry>
        </collision>
    </link>
   <joint
      name="camera"
      type="fixed">
      <origin
        xyz="0.05 0.022 0"
        rpy="0 1.57079632679 0" />
      <parent
        link="head_pitch" />
      <child
        link="camera" />
      <axis
        xyz="0 0 0" />
    </joint>
</robot>
